<?xml version="1.0" ?>
<!-- =================================================================================== -->
<!-- |    This document was autogenerated by xacro from cobotta.urdf.xacro             | -->
<!-- |    EDITING THIS FILE BY HAND IS NOT RECOMMENDED                                 | -->
<!-- =================================================================================== -->
<robot name="cobotta">
  <gazebo>
    <plugin filename="libgazebo_ros_control.so" name="gazebo_ros_control">
      <robotNamespace>/cobotta</robotNamespace>
    </plugin>
  </gazebo>
  <link name="world"/>
  <joint name="joint_w" type="fixed">
    <parent link="world"/>
    <child link="base_link"/>
  </joint>
  <link name="base_link">
    <visual>
      <origin rpy="0 0 0" xyz="0 0 0"/>
      <geometry>
        <mesh filename="package://grinding_descriptions/urdf/cobotta/base_link.dae" scale="1 1 1"/>
      </geometry>
    </visual>
    <collision>
      <origin rpy="0 0 0" xyz="0 0 0"/>
      <geometry>
        <mesh filename="package://grinding_descriptions/urdf/cobotta/base_link.dae" scale="1 1 1"/>
      </geometry>
    </collision>
    <inertial>
      <mass value="1.4"/>
      <origin rpy="0.000000 0.000000 0.000000" xyz="-0.021310 0.000002 0.044011"/>
      <inertia ixx="0.0026599999999999996" ixy="0.0" ixz="0.0" iyy="0.0026599999999999996" iyz="0.0" izz="0.00448"/>
    </inertial>
  </link>
  <link name="J1">
    <visual>
      <origin rpy="0 0 0" xyz="0 0 0"/>
      <geometry>
        <mesh filename="package://grinding_descriptions/urdf/cobotta/J1.dae" scale="1 1 1"/>
      </geometry>
    </visual>
    <collision>
      <origin rpy="0 0 0" xyz="0 0 0"/>
      <geometry>
        <mesh filename="package://grinding_descriptions/urdf/cobotta/J1.dae" scale="1 1 1"/>
      </geometry>
    </collision>
    <inertial>
      <mass value="1.29"/>
      <origin rpy="0.000000 0.000000 0.000000" xyz="0.000000 0.000000 0.15"/>
      <inertia ixx="0.002236" ixy="0.0" ixz="0.0" iyy="0.002236" iyz="0.0" izz="0.002322"/>
    </inertial>
  </link>
  <joint name="joint_1" type="revolute">
    <parent link="base_link"/>
    <child link="J1"/>
    <origin rpy="0.000000 0.000000 0.000000" xyz="0.000000 0.000000  0.108000"/>
    <axis xyz="-0.000000 -0.000000 1.000000"/>
    <limit effort="10" lower="-2.617994" upper="2.617994" velocity="0.383012504350156"/>
    <dynamics damping="0.001" friction="0.61"/>
  </joint>
  <transmission name="trans_1">
    <type>transmission_interface/SimpleTransmission</type>
    <joint name="joint_1">
      <hardwareInterface>PositionJointInterface</hardwareInterface>
    </joint>
    <actuator name="motor_1">
      <hardwareInterface>PositionJointInterface</hardwareInterface>
      <mechanicalReduction>1</mechanicalReduction>
    </actuator>
  </transmission>
  <link name="J2">
    <visual>
      <origin rpy="0 0 0" xyz="0 0 0"/>
      <geometry>
        <mesh filename="package://grinding_descriptions/urdf/cobotta/J2.dae" scale="1 1 1"/>
      </geometry>
    </visual>
    <collision>
      <origin rpy="0 0 0" xyz="0 0 0"/>
      <geometry>
        <mesh filename="package://grinding_descriptions/urdf/cobotta/J2.dae" scale="1 1 1"/>
      </geometry>
    </collision>
    <inertial>
      <mass value="0.39"/>
      <origin rpy="0.000000 0.000000 0.000000" xyz="-0.020000 0.100000 0.070000"/>
      <inertia ixx="0.0005557499999999999" ixy="0.0" ixz="0.0" iyy="0.0005557499999999999" iyz="0.0" izz="0.0001755"/>
    </inertial>
  </link>
  <joint name="joint_2" type="revolute">
    <parent link="J1"/>
    <child link="J2"/>
    <origin rpy="0.000000 0.000000 0.000000" xyz="0.000000 0.000000 0.072000"/>
    <axis xyz="-0.000000 1.000000 -0.000000"/>
    <limit effort="10" lower="-1.047198" upper="1.745329" velocity="0.37256670877697"/>
    <dynamics damping="0.001" friction="0.61"/>
  </joint>
  <transmission name="trans_2">
    <type>transmission_interface/SimpleTransmission</type>
    <joint name="joint_2">
      <hardwareInterface>PositionJointInterface</hardwareInterface>
    </joint>
    <actuator name="motor_2">
      <hardwareInterface>PositionJointInterface</hardwareInterface>
      <mechanicalReduction>1</mechanicalReduction>
    </actuator>
  </transmission>
  <link name="J3">
    <visual>
      <origin rpy="0 0 0" xyz="0 0 0"/>
      <geometry>
        <mesh filename="package://grinding_descriptions/urdf/cobotta/J3.dae" scale="1 1 1"/>
      </geometry>
    </visual>
    <collision>
      <origin rpy="0 0 0" xyz="0 0 0"/>
      <geometry>
        <mesh filename="package://grinding_descriptions/urdf/cobotta/J3.dae" scale="1 1 1"/>
      </geometry>
    </collision>
    <inertial>
      <mass value="0.35"/>
      <origin rpy="0.000000 0.000000 0.000000" xyz="-0.01000 0.020000 0.030000"/>
      <inertia ixx="0.0004316666666666666" ixy="0.0" ixz="0.0" iyy="0.0004316666666666666" iyz="0.0" izz="0.00015749999999999998"/>
    </inertial>
  </link>
  <joint name="joint_3" type="revolute">
    <parent link="J2"/>
    <child link="J3"/>
    <origin rpy="0.000000 0.000000 0.000000" xyz="0.000000 0.000000 0.165000"/>
    <axis xyz="-0.000000 1.000000 -0.000000"/>
    <limit effort="10" lower="0.3141593" upper="2.443461" velocity="0.68942250783028"/>
    <dynamics damping="0.001" friction="0.61"/>
  </joint>
  <transmission name="trans_3">
    <type>transmission_interface/SimpleTransmission</type>
    <joint name="joint_3">
      <hardwareInterface>PositionJointInterface</hardwareInterface>
    </joint>
    <actuator name="motor_3">
      <hardwareInterface>PositionJointInterface</hardwareInterface>
      <mechanicalReduction>1</mechanicalReduction>
    </actuator>
  </transmission>
  <link name="J4">
    <visual>
      <origin rpy="0 0 0" xyz="0 0 0"/>
      <geometry>
        <mesh filename="package://grinding_descriptions/urdf/cobotta/J4.dae" scale="1 1 1"/>
      </geometry>
    </visual>
    <collision>
      <origin rpy="0 0 0" xyz="0 0 0"/>
      <geometry>
        <mesh filename="package://grinding_descriptions/urdf/cobotta/J4.dae" scale="1 1 1"/>
      </geometry>
    </collision>
    <inertial>
      <mass value="0.35"/>
      <origin rpy="0.000000 0.000000 0.000000" xyz="0.0000 0.000000 0.055000"/>
      <inertia ixx="0.0004316666666666666" ixy="0.0" ixz="0.0" iyy="0.0004316666666666666" iyz="0.0" izz="0.00015749999999999998"/>
    </inertial>
  </link>
  <joint name="joint_4" type="revolute">
    <parent link="J3"/>
    <child link="J4"/>
    <origin rpy="0.000000 0.000000 0.000000" xyz="-0.012000 0.020000 0.088000"/>
    <axis xyz="-0.000000 -0.000000 1.000000"/>
    <limit effort="10" lower="-2.96706" upper="2.96706" velocity="0.702189591308619"/>
    <dynamics damping="0.001" friction="0.61"/>
  </joint>
  <transmission name="trans_4">
    <type>transmission_interface/SimpleTransmission</type>
    <joint name="joint_4">
      <hardwareInterface>PositionJointInterface</hardwareInterface>
    </joint>
    <actuator name="motor_4">
      <hardwareInterface>PositionJointInterface</hardwareInterface>
      <mechanicalReduction>1</mechanicalReduction>
    </actuator>
  </transmission>
  <link name="J5">
    <visual>
      <origin rpy="0 0 0" xyz="0 0 0"/>
      <geometry>
        <mesh filename="package://grinding_descriptions/urdf/cobotta/J5.dae" scale="1 1 1"/>
      </geometry>
    </visual>
    <collision>
      <origin rpy="0 0 0" xyz="0 0 0"/>
      <geometry>
        <mesh filename="package://grinding_descriptions/urdf/cobotta/J5.dae" scale="1 1 1"/>
      </geometry>
    </collision>
    <inertial>
      <mass value="0.19"/>
      <origin rpy="0.000000 0.000000 0.000000" xyz="0.000000 -0.040000 0.015000"/>
      <inertia ixx="9.974999999999999e-05" ixy="0.0" ixz="0.0" iyy="9.974999999999999e-05" iyz="0.0" izz="8.55e-05"/>
    </inertial>
  </link>
  <joint name="joint_5" type="revolute">
    <parent link="J4"/>
    <child link="J5"/>
    <origin rpy="0.000000 0.000000 0.000000" xyz="0.000000 -0.020000 0.089500"/>
    <axis xyz="-0.000000 1.000000 -0.000000"/>
    <limit effort="10" lower="-1.658063" upper="2.356194" velocity="0.702189591308619"/>
    <dynamics damping="0.001" friction="0.61"/>
  </joint>
  <transmission name="trans_5">
    <type>transmission_interface/SimpleTransmission</type>
    <joint name="joint_5">
      <hardwareInterface>PositionJointInterface</hardwareInterface>
    </joint>
    <actuator name="motor_5">
      <hardwareInterface>PositionJointInterface</hardwareInterface>
      <mechanicalReduction>1</mechanicalReduction>
    </actuator>
  </transmission>
  <link name="J6">
    <visual>
      <origin rpy="0 0 0" xyz="0 0 0"/>
      <geometry>
        <mesh filename="package://grinding_descriptions/urdf/cobotta/J6.dae" scale="1 1 1"/>
      </geometry>
    </visual>
    <collision>
      <origin rpy="0 0 0" xyz="0 0 0"/>
      <geometry>
        <mesh filename="package://grinding_descriptions/urdf/cobotta/J6.dae" scale="1 1 1"/>
      </geometry>
    </collision>
    <inertial>
      <mass value="0.03"/>
      <origin rpy="0.000000 0.000000 0.000000" xyz="0.000000 0.000000 0.000000"/>
      <inertia ixx="7e-06" ixy="0.0" ixz="0.0" iyy="7e-06" iyz="0.0" izz="1.35e-05"/>
    </inertial>
  </link>
  <joint name="joint_6" type="revolute">
    <parent link="J5"/>
    <child link="J6"/>
    <origin rpy="0.000000 0.000000 0.000000" xyz="0.000000 -0.044500 0.042000"/>
    <axis xyz="-0.000000 -0.000000 1.000000"/>
    <limit effort="10" lower="-2.96706" upper="2.96706" velocity="1.05386470893922"/>
    <dynamics damping="0.001" friction="0.61"/>
  </joint>
  <transmission name="trans_6">
    <type>transmission_interface/SimpleTransmission</type>
    <joint name="joint_6">
      <hardwareInterface>PositionJointInterface</hardwareInterface>
    </joint>
    <actuator name="motor_6">
      <hardwareInterface>PositionJointInterface</hardwareInterface>
      <mechanicalReduction>1</mechanicalReduction>
    </actuator>
  </transmission>
  <!-- Add end effector model -->
  <link name="spatula">
    <visual>
      <geometry>
        <mesh filename="package://grinding_descriptions/mesh/cobotta/jig_spatula.stl"/>
      </geometry>
    </visual>
  </link>
  <joint name="joint_spatula" type="fixed">
    <!-- 実際はグリッパの厚みでzが-0.036されるので注意 -->
    <!-- zはグリッパ考慮して最大0.07まではいけそう -->
    <origin rpy="0 0 -1.57079632679" xyz="0 -0.026 0.049"/>
    <parent link="J6"/>
    <child link="spatula"/>
  </joint>
  <link name="spatula_tip">
    <visual>
      <geometry>
        <box size="0 0 0"/>
      </geometry>
    </visual>
  </link>
  <joint name="joint_spatula_tip" type="fixed">
    <!-- 治具で0.06+ゴムベラ0.03 -->
    <origin rpy="-1.57079632679 0 -1.57079632679" xyz="0.09 0 0"/>
    <parent link="spatula"/>
    <child link="spatula_tip"/>
  </joint>
  <link name="pestle">
    <visual>
      <geometry>
        <mesh filename="package://grinding_descriptions/mesh/cobotta/jig_pestle_140.stl"/>
      </geometry>
    </visual>
  </link>
  <joint name="joint_pestle" type="fixed">
    <origin rpy="0 0 0" xyz="0 0 0"/>
    <parent link="J6"/>
    <child link="pestle"/>
  </joint>
  <link name="pestle_tip">
    <visual>
      <geometry>
        <box size="0 0 0"/>
      </geometry>
    </visual>
  </link>
  <joint name="joint_pestle_tip" type="fixed">
    <!-- for pestle -->
    <origin rpy="0 0 0" xyz="0 0 0.160"/>
    <parent link="pestle"/>
    <child link="pestle_tip"/>
  </joint>
</robot>
