<robot name="cobotta">
	<gazebo>
		<plugin name="gazebo_ros_control" filename="libgazebo_ros_control.so">
			<robotNamespace>/cobotta</robotNamespace>
		</plugin>
	</gazebo>
	<link name="world" />
	<joint name="joint_w" type="fixed">
		<parent link="world" />
		<child link="base_link" />
	</joint>
	<link name="base_link">
		<visual>
			<origin rpy="0 0 0" xyz="0 0 0" />
			<geometry>
				<mesh filename="package://grinding_descriptions/urdf/cobotta/base_link.stl"
					scale="1 1 1" />
			</geometry>
		</visual>
		<collision>
			<origin rpy="0 0 0" xyz="0 0 0" />
			<geometry>
				<mesh filename="package://grinding_descriptions/urdf/cobotta/base_link.stl"
					scale="1 1 1" />
			</geometry>
		</collision>
		<inertial>
			<mass value="1" />
			<origin rpy="0.000000 0.000000 0.000000" xyz="0.000000 0.000000 0.000000" />
			<inertia ixx="1" ixy="0" ixz="0" iyy="1" iyz="0" izz="1" />
		</inertial>
	</link>
	<link name="J1">
		<visual>
			<origin rpy="0 0 0" xyz="0 0 0" />
			<geometry>
				<mesh filename="package://grinding_descriptions/urdf/cobotta/J1.stl" scale="1 1 1" />
			</geometry>
		</visual>
		<collision>
			<origin rpy="0 0 0" xyz="0 0 0" />
			<geometry>
				<mesh filename="package://grinding_descriptions/urdf/cobotta/J1.stl" scale="1 1 1" />
			</geometry>
		</collision>
		<inertial>
			<mass value="1" />
			<origin rpy="0.000000 0.000000 0.000000" xyz="0.000000 0.000000 0.000000" />
			<inertia ixx="1" ixy="0" ixz="0" iyy="1" iyz="0" izz="1" />
		</inertial>
	</link>
	<joint name="joint_1" type="revolute">
		<parent link="base_link" />
		<child link="J1" />
		<origin rpy="0.000000 0.000000 0.000000" xyz="0.000000 0.000000 0.108000" />
		<axis xyz="-0.000000 -0.000000 1.000000" />
		<limit effort="1" lower="-2.617994" upper="2.617994" velocity="0.383012504350156" />
		<dynamics damping="0" friction="0" />
	</joint>
	<transmission name="trans_1">
		<type>transmission_interface/SimpleTransmission</type>
		<joint name="joint_1">
			<hardwareInterface>PositionJointInterface</hardwareInterface>
		</joint>
		<actuator name="motor_1">
			<hardwareInterface>PositionJointInterface</hardwareInterface>
			<mechanicalReduction>1</mechanicalReduction>
		</actuator>
	</transmission>
	<link name="J2">
		<visual>
			<origin rpy="0 0 0" xyz="0 0 0" />
			<geometry>
				<mesh filename="package://grinding_descriptions/urdf/cobotta/J2.stl" scale="1 1 1" />
			</geometry>
		</visual>
		<collision>
			<origin rpy="0 0 0" xyz="0 0 0" />
			<geometry>
				<mesh filename="package://grinding_descriptions/urdf/cobotta/J2.stl" scale="1 1 1" />
			</geometry>
		</collision>
		<inertial>
			<mass value="1" />
			<origin rpy="0.000000 0.000000 0.000000" xyz="0.000000 0.000000 0.000000" />
			<inertia ixx="1" ixy="0" ixz="0" iyy="1" iyz="0" izz="1" />
		</inertial>
	</link>
	<joint name="joint_2" type="revolute">
		<parent link="J1" />
		<child link="J2" />
		<origin rpy="0.000000 0.000000 0.000000" xyz="0.000000 0.000000 0.072000" />
		<axis xyz="-0.000000 1.000000 -0.000000" />
		<limit effort="1" lower="-1.047198" upper="1.745329" velocity="0.37256670877697" />
		<dynamics damping="0" friction="0" />
	</joint>
	<transmission name="trans_2">
		<type>transmission_interface/SimpleTransmission</type>
		<joint name="joint_2">
			<hardwareInterface>PositionJointInterface</hardwareInterface>
		</joint>
		<actuator name="motor_2">
			<hardwareInterface>PositionJointInterface</hardwareInterface>
			<mechanicalReduction>1</mechanicalReduction>
		</actuator>
	</transmission>
	<link name="J3">
		<visual>
			<origin rpy="0 0 0" xyz="0 0 0" />
			<geometry>
				<mesh filename="package://grinding_descriptions/urdf/cobotta/J3.stl" scale="1 1 1" />
			</geometry>
		</visual>
		<collision>
			<origin rpy="0 0 0" xyz="0 0 0" />
			<geometry>
				<mesh filename="package://grinding_descriptions/urdf/cobotta/J3.stl" scale="1 1 1" />
			</geometry>
		</collision>
		<inertial>
			<mass value="1" />
			<origin rpy="0.000000 0.000000 0.000000" xyz="0.000000 0.000000 0.000000" />
			<inertia ixx="1" ixy="0" ixz="0" iyy="1" iyz="0" izz="1" />
		</inertial>
	</link>
	<joint name="joint_3" type="revolute">
		<parent link="J2" />
		<child link="J3" />
		<origin rpy="0.000000 0.000000 0.000000" xyz="0.000000 0.000000 0.165000" />
		<axis xyz="-0.000000 1.000000 -0.000000" />
		<limit effort="1" lower="0.3141593" upper="2.443461" velocity="0.68942250783028" />
		<dynamics damping="0" friction="0" />
	</joint>
	<transmission name="trans_3">
		<type>transmission_interface/SimpleTransmission</type>
		<joint name="joint_3">
			<hardwareInterface>PositionJointInterface</hardwareInterface>
		</joint>
		<actuator name="motor_3">
			<hardwareInterface>PositionJointInterface</hardwareInterface>
			<mechanicalReduction>1</mechanicalReduction>
		</actuator>
	</transmission>
	<link name="J4">
		<visual>
			<origin rpy="0 0 0" xyz="0 0 0" />
			<geometry>
				<mesh filename="package://grinding_descriptions/urdf/cobotta/J4.stl" scale="1 1 1" />
			</geometry>
		</visual>
		<collision>
			<origin rpy="0 0 0" xyz="0 0 0" />
			<geometry>
				<mesh filename="package://grinding_descriptions/urdf/cobotta/J4.stl" scale="1 1 1" />
			</geometry>
		</collision>
		<inertial>
			<mass value="1" />
			<origin rpy="0.000000 0.000000 0.000000" xyz="0.000000 0.000000 0.000000" />
			<inertia ixx="1" ixy="0" ixz="0" iyy="1" iyz="0" izz="1" />
		</inertial>
	</link>
	<joint name="joint_4" type="revolute">
		<parent link="J3" />
		<child link="J4" />
		<origin rpy="0.000000 0.000000 0.000000" xyz="-0.012000 0.020000 0.088000" />
		<axis xyz="-0.000000 -0.000000 1.000000" />
		<limit effort="1" lower="-2.96706" upper="2.96706" velocity="0.702189591308619" />
		<dynamics damping="0" friction="0" />
	</joint>
	<transmission name="trans_4">
		<type>transmission_interface/SimpleTransmission</type>
		<joint name="joint_4">
			<hardwareInterface>PositionJointInterface</hardwareInterface>
		</joint>
		<actuator name="motor_4">
			<hardwareInterface>PositionJointInterface</hardwareInterface>
			<mechanicalReduction>1</mechanicalReduction>
		</actuator>
	</transmission>
	<link name="J5">
		<visual>
			<origin rpy="0 0 0" xyz="0 0 0" />
			<geometry>
				<mesh filename="package://grinding_descriptions/urdf/cobotta/J5.stl" scale="1 1 1" />
			</geometry>
		</visual>
		<collision>
			<origin rpy="0 0 0" xyz="0 0 0" />
			<geometry>
				<mesh filename="package://grinding_descriptions/urdf/cobotta/J5.stl" scale="1 1 1" />
			</geometry>
		</collision>
		<inertial>
			<mass value="1" />
			<origin rpy="0.000000 0.000000 0.000000" xyz="0.000000 0.000000 0.000000" />
			<inertia ixx="1" ixy="0" ixz="0" iyy="1" iyz="0" izz="1" />
		</inertial>
	</link>
	<joint name="joint_5" type="revolute">
		<parent link="J4" />
		<child link="J5" />
		<origin rpy="0.000000 0.000000 0.000000" xyz="0.000000 -0.020000 0.089500" />
		<axis xyz="-0.000000 1.000000 -0.000000" />
		<limit effort="1" lower="-1.658063" upper="2.356194" velocity="0.702189591308619" />
		<dynamics damping="0" friction="0" />
	</joint>
	<transmission name="trans_5">
		<type>transmission_interface/SimpleTransmission</type>
		<joint name="joint_5">
			<hardwareInterface>PositionJointInterface</hardwareInterface>
		</joint>
		<actuator name="motor_5">
			<hardwareInterface>PositionJointInterface</hardwareInterface>
			<mechanicalReduction>1</mechanicalReduction>
		</actuator>
	</transmission>
	<link name="J6">
		<visual>
			<origin rpy="0 0 0" xyz="0 0 0" />
			<geometry>
				<mesh filename="package://grinding_descriptions/urdf/cobotta/J6.stl" scale="1 1 1" />
			</geometry>
		</visual>
		<collision>
			<origin rpy="0 0 0" xyz="0 0 0" />
			<geometry>
				<mesh filename="package://grinding_descriptions/urdf/cobotta/J6.stl" scale="1 1 1" />
			</geometry>
		</collision>
		<inertial>
			<mass value="1" />
			<origin rpy="0.000000 0.000000 0.000000" xyz="0.000000 0.000000 0.000000" />
			<inertia ixx="1" ixy="0" ixz="0" iyy="1" iyz="0" izz="1" />
		</inertial>
	</link>
	<joint name="joint_6" type="revolute">
		<parent link="J5" />
		<child link="J6" />
		<origin rpy="0.000000 0.000000 0.000000" xyz="0.000000 -0.044500 0.042000" />
		<axis xyz="-0.000000 -0.000000 1.000000" />
		<limit effort="1" lower="-2.96706" upper="2.96706" velocity="1.05386470893922" />
		<dynamics damping="0" friction="0" />
	</joint>
	<transmission name="trans_6">
		<type>transmission_interface/SimpleTransmission</type>
		<joint name="joint_6">
			<hardwareInterface>PositionJointInterface</hardwareInterface>
		</joint>
		<actuator name="motor_6">
			<hardwareInterface>PositionJointInterface</hardwareInterface>
			<mechanicalReduction>1</mechanicalReduction>
		</actuator>
	</transmission>

		<!-- Add end effector model -->
	<link name="spatula">
		<visual>
			<geometry>
				<mesh filename="package://grinding_descriptions/mesh/cobotta/jig_spatula.stl" />
			</geometry>
		</visual>
	</link>
	<joint name="joint_spatula" type="fixed">
		<!-- 実際はグリッパの厚みでzが-0.036されるので注意 -->
		<!-- zはグリッパ考慮して最大0.07まではいけそう -->
		<origin rpy="0 0 -1.57079632679" xyz="0 -0.026 0.049" />
		<parent link="J6" />
		<child link="spatula" />
	</joint>

	<link name="spatula_tip">
		<visual>
			<geometry>
				<box size="0 0 0" />
			</geometry>
		</visual>
	</link>
	<joint name="joint_spatula_tip" type="fixed">
		<!-- 治具で0.06+ゴムベラ0.03 -->
		<origin rpy="-1.57079632679 0 -1.57079632679" xyz="0.09 0 0" />
		<parent link="spatula" />
		<child link="spatula_tip" />
	</joint>


	<link name="pestle">
		<visual>
			<geometry>
				<mesh filename="package://grinding_descriptions/mesh/cobotta/jig_pestle_140.stl" />
			</geometry>
		</visual>
	</link>
	<joint name="joint_pestle" type="fixed">
		<origin rpy="0 0 0" xyz="0 0 0" />
		<parent link="J6" />
		<child link="pestle" />
	</joint>

	<link name="pestle_tip">
		<visual>
			<geometry>
				<box size="0 0 0" />
			</geometry>
		</visual>
	</link>
	<joint name="joint_pestle_tip" type="fixed">
		<!-- for pestle -->
		<origin rpy="0 0 0" xyz="0 0 0.160" />
		<parent link="pestle" />
		<child link="pestle_tip" />
	</joint>

</robot>