<robot name="cobotta">
	<gazebo>
		<plugin name="gazebo_ros_control" filename="libgazebo_ros_control.so">
			<robotNamespace>/cobotta</robotNamespace>
		</plugin>
	</gazebo>
	<link name="world" />
	<joint name="joint_w" type="fixed">
		<parent link="world" />
		<child link="base_link" />
	</joint>
	<link name="base_link">
		<visual>
			<origin rpy="0 0 0" xyz="0 0 0" />
			<geometry>
				<mesh filename="package://denso_robot_descriptions/cobotta_description/base_link.stl" />
			</geometry>
		</visual>
		<collision>
			<origin rpy="0 0 0" xyz="0 0 0" />
			<geometry>
				<mesh filename="package://denso_robot_descriptions/cobotta_description/base_link.stl" />
			</geometry>
		</collision>
		<inertial>
			<mass value="1" />
			<origin rpy="0.000000 0.000000 0.000000" xyz="0.000000 0.000000 0.000000" />
			<inertia ixx="1" ixy="0" ixz="0" iyy="1" iyz="0" izz="1" />
		</inertial>
	</link>
	<link name="J1">
		<visual>
			<origin rpy="0 0 0" xyz="0 0 0" />
			<geometry>
				<mesh filename="package://denso_robot_descriptions/cobotta_description/J1.stl" />
			</geometry>
		</visual>
		<collision>
			<origin rpy="0 0 0" xyz="0 0 0" />
			<geometry>
				<mesh filename="package://denso_robot_descriptions/cobotta_description/J1.stl" />
			</geometry>
		</collision>
		<inertial>
			<mass value="1" />
			<origin rpy="0.000000 0.000000 0.000000" xyz="0.000000 0.000000 0.000000" />
			<inertia ixx="1" ixy="0" ixz="0" iyy="1" iyz="0" izz="1" />
		</inertial>
	</link>
	<joint name="joint_1" type="revolute">
		<parent link="base_link" />
		<child link="J1" />
		<origin rpy="0.000000 0.000000 0.000000" xyz="0.000000 0.000000 0.000000" />
		<axis xyz="-0.000000 -0.000000 1.000000" />
		<limit effort="1" lower="-2.61799387799149" upper="2.61799387799149" velocity="0.383012504350156" />
		<dynamics damping="0" friction="0" />
	</joint>
	<transmission name="trans_1">
		<type>transmission_interface/SimpleTransmission</type>
		<joint name="joint_1">
			<hardwareInterface>hardware_interface/PositionJointInterface</hardwareInterface>
		</joint>
		<actuator name="motor_1">
			<hardwareInterface>hardware_interface/PositionJointInterface</hardwareInterface>
			<mechanicalReduction>1</mechanicalReduction>
		</actuator>
	</transmission>
	<link name="J2">
		<visual>
			<origin rpy="0 0 0" xyz="0 0 0" />
			<geometry>
				<mesh filename="package://denso_robot_descriptions/cobotta_description/J2.stl" />
			</geometry>
		</visual>
		<collision>
			<origin rpy="0 0 0" xyz="0 0 0" />
			<geometry>
				<mesh filename="package://denso_robot_descriptions/cobotta_description/J2.stl" />
			</geometry>
		</collision>
		<inertial>
			<mass value="1" />
			<origin rpy="0.000000 0.000000 0.000000" xyz="0.000000 0.000000 0.000000" />
			<inertia ixx="1" ixy="0" ixz="0" iyy="1" iyz="0" izz="1" />
		</inertial>
	</link>
	<joint name="joint_2" type="revolute">
		<parent link="J1" />
		<child link="J2" />
		<origin rpy="0.000000 0.000000 0.000000" xyz="0.000000 0.000000 0.180000" />
		<axis xyz="-0.000000 1.000000 -0.000000" />
		<limit effort="1" lower="-1.0471975511966" upper="1.74532925199433" velocity="0.37256670877697" />
		<dynamics damping="0" friction="0" />
	</joint>
	<transmission name="trans_2">
		<type>transmission_interface/SimpleTransmission</type>
		<joint name="joint_2">
			<hardwareInterface>hardware_interface/PositionJointInterface</hardwareInterface>
		</joint>
		<actuator name="motor_2">
			<hardwareInterface>hardware_interface/PositionJointInterface</hardwareInterface>
			<mechanicalReduction>1</mechanicalReduction>
		</actuator>
	</transmission>
	<link name="J3">
		<visual>
			<origin rpy="0 0 0" xyz="0 0 0" />
			<geometry>
				<mesh filename="package://denso_robot_descriptions/cobotta_description/J3.stl" />
			</geometry>
		</visual>
		<collision>
			<origin rpy="0 0 0" xyz="0 0 0" />
			<geometry>
				<mesh filename="package://denso_robot_descriptions/cobotta_description/J3.stl" />
			</geometry>
		</collision>
		<inertial>
			<mass value="1" />
			<origin rpy="0.000000 0.000000 0.000000" xyz="0.000000 0.000000 0.000000" />
			<inertia ixx="1" ixy="0" ixz="0" iyy="1" iyz="0" izz="1" />
		</inertial>
	</link>
	<joint name="joint_3" type="revolute">
		<parent link="J2" />
		<child link="J3" />
		<origin rpy="0.000000 0.000000 0.000000" xyz="0.000000 0.000000 0.165000" />
		<axis xyz="-0.000000 1.000000 -0.000000" />
		<limit effort="1" lower="0.314159265358979" upper="2.44346095279206" velocity="0.68942250783028" />
		<dynamics damping="0" friction="0" />
	</joint>
	<transmission name="trans_3">
		<type>transmission_interface/SimpleTransmission</type>
		<joint name="joint_3">
			<hardwareInterface>hardware_interface/PositionJointInterface</hardwareInterface>
		</joint>
		<actuator name="motor_3">
			<hardwareInterface>hardware_interface/PositionJointInterface</hardwareInterface>
			<mechanicalReduction>1</mechanicalReduction>
		</actuator>
	</transmission>
	<link name="J4">
		<visual>
			<origin rpy="0 0 0" xyz="0 0 0" />
			<geometry>
				<mesh filename="package://denso_robot_descriptions/cobotta_description/J4.stl" />
			</geometry>
		</visual>
		<collision>
			<origin rpy="0 0 0" xyz="0 0 0" />
			<geometry>
				<mesh filename="package://denso_robot_descriptions/cobotta_description/J4.stl" />
			</geometry>
		</collision>
		<inertial>
			<mass value="1" />
			<origin rpy="0.000000 0.000000 0.000000" xyz="0.000000 0.000000 0.000000" />
			<inertia ixx="1" ixy="0" ixz="0" iyy="1" iyz="0" izz="1" />
		</inertial>
	</link>
	<joint name="joint_4" type="revolute">
		<parent link="J3" />
		<child link="J4" />
		<origin rpy="0.000000 0.000000 0.000000" xyz="-0.012000 0.020000 -0.345000" />
		<axis xyz="-0.000000 -0.000000 1.000000" />
		<limit effort="1" lower="-2.96705972839036" upper="2.96705972839036" velocity="0.702189591308619" />
		<dynamics damping="0" friction="0" />
	</joint>
	<transmission name="trans_4">
		<type>transmission_interface/SimpleTransmission</type>
		<joint name="joint_4">
			<hardwareInterface>hardware_interface/PositionJointInterface</hardwareInterface>
		</joint>
		<actuator name="motor_4">
			<hardwareInterface>hardware_interface/PositionJointInterface</hardwareInterface>
			<mechanicalReduction>1</mechanicalReduction>
		</actuator>
	</transmission>
	<link name="J5">
		<visual>
			<origin rpy="0 0 0" xyz="0 0 0" />
			<geometry>
				<mesh filename="package://denso_robot_descriptions/cobotta_description/J5.stl" />
			</geometry>
		</visual>
		<collision>
			<origin rpy="0 0 0" xyz="0 0 0" />
			<geometry>
				<mesh filename="package://denso_robot_descriptions/cobotta_description/J5.stl" />
			</geometry>
		</collision>
		<inertial>
			<mass value="1" />
			<origin rpy="0.000000 0.000000 0.000000" xyz="0.000000 0.000000 0.000000" />
			<inertia ixx="1" ixy="0" ixz="0" iyy="1" iyz="0" izz="1" />
		</inertial>
	</link>
	<joint name="joint_5" type="revolute">
		<parent link="J4" />
		<child link="J5" />
		<origin rpy="0.000000 0.000000 0.000000" xyz="0.000000 -0.020000 0.522500" />
		<axis xyz="-0.000000 1.000000 -0.000000" />
		<limit effort="1" lower="-1.65806278939461" upper="2.35619449019234" velocity="0.702189591308619" />
		<dynamics damping="0" friction="0" />
	</joint>
	<transmission name="trans_5">
		<type>transmission_interface/SimpleTransmission</type>
		<joint name="joint_5">
			<hardwareInterface>hardware_interface/PositionJointInterface</hardwareInterface>
		</joint>
		<actuator name="motor_5">
			<hardwareInterface>hardware_interface/PositionJointInterface</hardwareInterface>
			<mechanicalReduction>1</mechanicalReduction>
		</actuator>
	</transmission>
	<link name="J6">
		<visual>
			<origin rpy="0 0 0" xyz="0 0 0" />
			<geometry>
				<mesh filename="package://denso_robot_descriptions/cobotta_description/J6.stl" />
			</geometry>
		</visual>
		<collision>
			<origin rpy="0 0 0" xyz="0 0 0" />
			<geometry>
				<mesh filename="package://denso_robot_descriptions/cobotta_description/J6.stl" />
			</geometry>
		</collision>
		<inertial>
			<mass value="1" />
			<origin rpy="0.000000 0.000000 0.000000" xyz="0.000000 0.000000 0.000000" />
			<inertia ixx="1" ixy="0" ixz="0" iyy="1" iyz="0" izz="1" />
		</inertial>
	</link>
	<joint name="joint_6" type="revolute">
		<parent link="J5" />
		<child link="J6" />
		<origin rpy="0.000000 0.000000 0.000000" xyz="0.000000 -0.044500 0.042000" />
		<axis xyz="-0.000000 -0.000000 1.000000" />
		<limit effort="1" lower="-2.96705972839036" upper="2.96705972839036" velocity="1.05386470893922" />
		<dynamics damping="0" friction="0" />
	</joint>
	<transmission name="trans_6">
		<type>transmission_interface/SimpleTransmission</type>
		<joint name="joint_6">
			<hardwareInterface>hardware_interface/PositionJointInterface</hardwareInterface>
		</joint>
		<actuator name="motor_6">
			<hardwareInterface>hardware_interface/PositionJointInterface</hardwareInterface>
			<mechanicalReduction>1</mechanicalReduction>
		</actuator>
	</transmission>
</robot>

	