<?xml version="1.0" ?>
<!-- =================================================================================== -->
<!-- |    This document was autogenerated by xacro from cobotta.urdf.xacro             | -->
<!-- |    EDITING THIS FILE BY HAND IS NOT RECOMMENDED                                 | -->
<!-- =================================================================================== -->
<robot name="stdcb">
  <!-- main -->
  <link name="world"/>
  <joint name="joint_w" type="fixed">
    <origin rpy="0 0 0" xyz="0 0 0"/>
    <parent link="world"/>
    <child link="base_link"/>
  </joint>
  <link name="base_link">
    <visual>
      <geometry>
        <mesh filename="package://denso_descr/stdcb_description/base_link.stl"/>
      </geometry>
    </visual>
  </link>
  <joint name="joint_1" type="revolute">
    <origin rpy="0 0 0" xyz="0 0 0"/>
    <axis xyz="0 0 1"/>
    <limit effort="0" lower="-2.61799387799149" upper="2.61799387799149" velocity="0"/>
    <parent link="base_link"/>
    <child link="J1"/>
  </joint>
  <link name="J1">
    <visual>
      <geometry>
        <mesh filename="package://denso_descr/stdcb_description/J1.stl"/>
      </geometry>
    </visual>
  </link>
  <joint name="joint_2" type="revolute">
    <origin rpy="0 0 0" xyz="0 0 0.18"/>
    <axis xyz="0 1 0"/>
    <limit effort="0" lower="-1.0471975511966" upper="1.74532925199433" velocity="0"/>
    <parent link="J1"/>
    <child link="J2"/>
  </joint>
  <link name="J2">
    <visual>
      <geometry>
        <mesh filename="package://denso_descr/stdcb_description/J2.stl"/>
      </geometry>
    </visual>
  </link>
  <joint name="joint_3" type="revolute">
    <origin rpy="0 0 0" xyz="0 0 0.165"/>
    <axis xyz="0 1 0"/>
    <limit effort="0" lower="0.314159265358979" upper="2.44346095279206" velocity="0"/>
    <parent link="J2"/>
    <child link="J3"/>
  </joint>
  <link name="J3">
    <visual>
      <geometry>
        <mesh filename="package://denso_descr/stdcb_description/J3.stl"/>
      </geometry>
    </visual>
  </link>
  <joint name="joint_4" type="revolute">
    <origin rpy="0 0 0" xyz="-0.012 0.02 -0.345"/>
    <axis xyz="0 0 1"/>
    <limit effort="0" lower="-2.96705972839036" upper="2.96705972839036" velocity="0"/>
    <parent link="J3"/>
    <child link="J4"/>
  </joint>
  <link name="J4">
    <visual>
      <geometry>
        <mesh filename="package://denso_descr/stdcb_description/J4.stl"/>
      </geometry>
    </visual>
  </link>
  <joint name="joint_5" type="revolute">
    <origin rpy="0 0 0" xyz="0 -0.02 0.52225"/>
    <axis xyz="0 1 0"/>
    <limit effort="0" lower="-1.65806278939461" upper="2.35619449019234" velocity="0"/>
    <parent link="J4"/>
    <child link="J5"/>
  </joint>
  <link name="J5">
    <visual>
      <geometry>
        <mesh filename="package://denso_descr/stdcb_description/J5.stl"/>
      </geometry>
    </visual>
  </link>
  <joint name="joint_6" type="revolute">
    <origin rpy="0 0 0" xyz="0 -0.0445 0.042"/>
    <axis xyz="0 0 1"/>
    <limit effort="0" lower="-2.96705972839036" upper="2.96705972839036" velocity="0"/>
    <parent link="J5"/>
    <child link="J6"/>
  </joint>
  <link name="J6">
    <visual>
      <geometry>
        <mesh filename="package://denso_descr/stdcb_description/J6.stl"/>
      </geometry>
    </visual>
  </link>
  <joint name="joint_pestle" type="fixed">
    <origin rpy="0 0 0" xyz="0 0 0"/>
    <parent link="J6"/>
    <child link="pestle"/>
  </joint>
  <link name="pestle">
    <visual>
      <geometry>
        <mesh filename="package://grinding_descriptions/mesh/jig_pestle_170.stl"/>
      </geometry>
    </visual>
  </link>
</robot>

